Workbook

Sheet Лист3 (2)
M1: Курс | N1: 2.85
B2: .2025 РОЗА | C2: кол-во | D2: цена | F2: там | G2: c/c | H2: rb | I2: ss | J2: ssnew | K2: gomel | L2: цена | M2: сп | N2: BYN | O2: сп BYN
A3: =[1]Лист4!A174 -> 8 | B3: =[1]Лист4!C174 -> AKM05 Пион Сара Бернард | C3: =[1]Лист4!D174 -> 50 | D3: =[1]Лист4!F174 -> 0.8 | E3: =D3*C3 -> 40 | F3: =D3*1.18*0.07 -> 0.06608 | G3: =ROUND((((D3*1.15)*1.18)+F3+0.14)*1.2,2) -> 1.55 | H3: =ROUNDUP(G3*1.04*$N$1,2) -> 4.6 | I3: =ROUNDUP(G3*1.2*$N$1,2) -> 5.31 | J3: =ROUNDUP(G3*1.03*$N$1,2) -> 4.56 | K3: =N3*0.95 -> 0 | M3: =ROUNDUP(L3*0.88,2) -> 0 | N3: =ROUNDUP(L3*$N$1,2) -> 0 | O3: =ROUNDUP(N3*0.88,2) -> 0 | P3: =G3*C3 -> 77.5 | Q3: =L3*C3 -> 0 | R3: =Q3-P3 -> -77.5 | T3: Paeo L Sara Bernhard
A4: =[1]Лист4!A175 -> 8 | B4: =[1]Лист4!C175 -> AKM06 Пион Сара Бернард | C4: =[1]Лист4!D175 -> 50 | D4: =[1]Лист4!F175 -> 0.98 | E4: =D4*C4 -> 49 | F4: =D4*1.18*0.07 -> 0.080948 | G4: =ROUND((((D4*1.15)*1.18)+F4+0.14)*1.2,2) -> 1.86 | H4: =ROUNDUP(G4*1.04*$N$1,2) -> 5.52 | I4: =ROUNDUP(G4*1.2*$N$1,2) -> 6.37 | J4: =ROUNDUP(G4*1.03*$N$1,2) -> 5.47 | K4: =N4*0.95 -> 0 | M4: =ROUNDUP(L4*0.88,2) -> 0 | N4: =ROUNDUP(L4*$N$1,2) -> 0 | O4: =ROUNDUP(N4*0.88,2) -> 0 | P4: =G4*C4 -> 93 | Q4: =L4*C4 -> 0 | R4: =Q4-P4 -> -93 | T4: Paeo L Sara Bernhard
A5: =[1]Лист4!A137 -> 8 | B5: =[1]Лист4!C137 -> AKM12 Гортензия Мэджик корал | C5: =[1]Лист4!D137 -> 10 | D5: =[1]Лист4!F137 -> 2 | E5: =D5*C5 -> 20 | F5: =D5*1.18*0.07 -> 0.1652 | G5: =ROUND((((D5*1.15)*1.18)+F5+0.14)*1.2,2) -> 3.62 | H5: =ROUNDUP(G5*1.04*$N$1,2) -> 10.73 | I5: =ROUNDUP(G5*1.2*$N$1,2) -> 12.39 | J5: =ROUNDUP(G5*1.03*$N$1,2) -> 10.63 | K5: =N5*0.95 -> 0 | M5: =ROUNDUP(L5*0.88,2) -> 0 | N5: =ROUNDUP(L5*$N$1,2) -> 0 | O5: =ROUNDUP(N5*0.88,2) -> 0 | P5: =G5*C5 -> 36.2 | Q5: =L5*C5 -> 0 | R5: =Q5-P5 -> -36.2 | T5: Hydr M Mag Coral
A6: =[1]Лист4!A151 -> 8 | B6: =[1]Лист4!C151 -> AKM12 Лимониум фиолетовый | C6: =[1]Лист4!D151 -> 25 | D6: =[1]Лист4!F151 -> 0.63 | E6: =D6*C6 -> 15.75 | F6: =D6*1.18*0.07 -> 0.052038 | G6: =ROUND((((D6*1.15)*1.18)+F6+0.14)*1.2,2) -> 1.26 | H6: =ROUNDUP(G6*1.04*$N$1,2) -> 3.74 | I6: =ROUNDUP(G6*1.2*$N$1,2) -> 4.31 | J6: =ROUNDUP(G6*1.03*$N$1,2) -> 3.7 | K6: =N6*0.95 -> 0 | M6: =ROUNDUP(L6*0.88,2) -> 0 | N6: =ROUNDUP(L6*$N$1,2) -> 0 | O6: =ROUNDUP(N6*0.88,2) -> 0 | P6: =G6*C6 -> 31.5 | Q6: =L6*C6 -> 0 | R6: =Q6-P6 -> -31.5 | T6: Lim Maine Blue
A7: =[1]Лист4!A168 -> 8 | B7: =[1]Лист4!C168 -> AKM12 Пион Александр Флейминг | C7: =[1]Лист4!D168 -> 50 | D7: =[1]Лист4!F168 -> 0.98 | E7: =D7*C7 -> 49 | F7: =D7*1.18*0.07 -> 0.080948 | G7: =ROUND((((D7*1.15)*1.18)+F7+0.14)*1.2,2) -> 1.86 | H7: =ROUNDUP(G7*1.04*$N$1,2) -> 5.52 | I7: =ROUNDUP(G7*1.2*$N$1,2) -> 6.37 | J7: =ROUNDUP(G7*1.03*$N$1,2) -> 5.47 | K7: =N7*0.95 -> 0 | M7: =ROUNDUP(L7*0.88,2) -> 0 | N7: =ROUNDUP(L7*$N$1,2) -> 0 | O7: =ROUNDUP(N7*0.88,2) -> 0 | P7: =G7*C7 -> 93 | Q7: =L7*C7 -> 0 | R7: =Q7-P7 -> -93 | T7: Paeo L Alex Fleming
A8: =[1]Лист4!A167 -> 8 | B8: =[1]Лист4!C167 -> AKM12 Пион Алертие | C8: =[1]Лист4!D167 -> 60 | D8: =[1]Лист4!F167 -> 0.71 | E8: =D8*C8 -> 42.6 | F8: =D8*1.18*0.07 -> 0.058646 | G8: =ROUND((((D8*1.15)*1.18)+F8+0.14)*1.2,2) -> 1.39 | H8: =ROUNDUP(G8*1.04*$N$1,2) -> 4.12 | I8: =ROUNDUP(G8*1.2*$N$1,2) -> 4.76 | J8: =ROUNDUP(G8*1.03*$N$1,2) -> 4.09 | K8: =N8*0.95 -> 0 | M8: =ROUNDUP(L8*0.88,2) -> 0 | N8: =ROUNDUP(L8*$N$1,2) -> 0 | O8: =ROUNDUP(N8*0.88,2) -> 0 | P8: =G8*C8 -> 83.4 | Q8: =L8*C8 -> 0 | R8: =Q8-P8 -> -83.4 | T8: Paeo L Alertie
A9: =[1]Лист4!A169 -> 8 | B9: =[1]Лист4!C169 -> AKM12 Пион Дюшес белый | C9: =[1]Лист4!D169 -> 40 | D9: =[1]Лист4!F169 -> 0.61 | E9: =D9*C9 -> 24.4 | F9: =D9*1.18*0.07 -> 0.050386 | G9: =ROUND((((D9*1.15)*1.18)+F9+0.14)*1.2,2) -> 1.22 | H9: =ROUNDUP(G9*1.04*$N$1,2) -> 3.62 | I9: =ROUNDUP(G9*1.2*$N$1,2) -> 4.18 | J9: =ROUNDUP(G9*1.03*$N$1,2) -> 3.59 | K9: =N9*0.95 -> 0 | M9: =ROUNDUP(L9*0.88,2) -> 0 | N9: =ROUNDUP(L9*$N$1,2) -> 0 | O9: =ROUNDUP(N9*0.88,2) -> 0 | P9: =G9*C9 -> 48.8 | Q9: =L9*C9 -> 0 | R9: =Q9-P9 -> -48.8 | T9: Paeo L Duches D Nemo
A10: =[1]Лист4!A170 -> 8 | B10: =[1]Лист4!C170 -> AKM12 Пион Канзас | C10: =[1]Лист4!D170 -> 50 | D10: =[1]Лист4!F170 -> 0.77 | E10: =D10*C10 -> 38.5 | F10: =D10*1.18*0.07 -> 0.063602 | G10: =ROUND((((D10*1.15)*1.18)+F10+0.14)*1.2,2) -> 1.5 | H10: =ROUNDUP(G10*1.04*$N$1,2) -> 4.45 | I10: =ROUNDUP(G10*1.2*$N$1,2) -> 5.13 | J10: =ROUNDUP(G10*1.03*$N$1,2) -> 4.41 | K10: =N10*0.95 -> 0 | M10: =ROUNDUP(L10*0.88,2) -> 0 | N10: =ROUNDUP(L10*$N$1,2) -> 0 | O10: =ROUNDUP(N10*0.88,2) -> 0 | P10: =G10*C10 -> 75 | Q10: =L10*C10 -> 0 | R10: =Q10-P10 -> -75 | T10: Paeo L Kansas
A11: =[1]Лист4!A165 -> 8 | B11: =[1]Лист4!C165 -> AKM12 Пион Корал Сансет | C11: =[1]Лист4!D165 -> 40 | D11: =[1]Лист4!F165 -> 0.61 | E11: =D11*C11 -> 24.4 | F11: =D11*1.18*0.07 -> 0.050386 | G11: =ROUND((((D11*1.15)*1.18)+F11+0.14)*1.2,2) -> 1.22 | H11: =ROUNDUP(G11*1.04*$N$1,2) -> 3.62 | I11: =ROUNDUP(G11*1.2*$N$1,2) -> 4.18 | J11: =ROUNDUP(G11*1.03*$N$1,2) -> 3.59 | K11: =N11*0.95 -> 0 | M11: =ROUNDUP(L11*0.88,2) -> 0 | N11: =ROUNDUP(L11*$N$1,2) -> 0 | O11: =ROUNDUP(N11*0.88,2) -> 0 | P11: =G11*C11 -> 48.8 | Q11: =L11*C11 -> 0 | R11: =Q11-P11 -> -48.8 | T11: Paeo Coral Sunset
A12: =[1]Лист4!A14 -> 1 | B12: =[1]Лист4!C14 -> AKM12 Роза ветваистая париж Розевер 60 | C12: =[1]Лист4!D14 -> 30 | D12: =[1]Лист4!F14 -> 0.82 | E12: =D12*C12 -> 24.6 | F12: =D12*1.18*0.07 -> 0.067732 | G12: =ROUND((((D12*1.15)*1.18)+F12+0.14)*1.2,2) -> 1.58 | H12: =ROUNDUP(G12*1.04*$N$1,2) -> 4.69 | I12: =ROUNDUP(G12*1.2*$N$1,2) -> 5.41 | J12: =ROUNDUP(G12*1.03*$N$1,2) -> 4.64 | K12: =N12*0.95 -> 0 | M12: =ROUNDUP(L12*0.88,2) -> 0 | N12: =ROUNDUP(L12*$N$1,2) -> 0 | O12: =ROUNDUP(N12*0.88,2) -> 0 | P12: =G12*C12 -> 47.4 | Q12: =L12*C12 -> 0 | R12: =Q12-P12 -> -47.4 | T12: R Tr Paris Rosever
A13: =[1]Лист4!A7 -> 1 | B13: =[1]Лист4!C7 -> AKM12 Роза ветвистая Пинк Дименсион NL 50 | C13: =[1]Лист4!D7 -> 30 | D13: =[1]Лист4!F7 -> 0.88 | E13: =D13*C13 -> 26.4 | F13: =D13*1.18*0.07 -> 0.072688 | G13: =ROUND((((D13*1.15)*1.18)+F13+0.14)*1.2,2) -> 1.69 | H13: =ROUNDUP(G13*1.04*$N$1,2) -> 5.01 | I13: =ROUNDUP(G13*1.2*$N$1,2) -> 5.78 | J13: =ROUNDUP(G13*1.03*$N$1,2) -> 4.97 | K13: =N13*0.95 -> 0 | M13: =ROUNDUP(L13*0.88,2) -> 0 | N13: =ROUNDUP(L13*$N$1,2) -> 0 | O13: =ROUNDUP(N13*0.88,2) -> 0 | P13: =G13*C13 -> 50.7 | Q13: =L13*C13 -> 0 | R13: =Q13-P13 -> -50.7 | T13: R Tr Pink Dimension
A14: =[1]Лист4!A16 -> 1 | B14: =[1]Лист4!C16 -> AKM12 Роза ветвистая Сноу трендсетр NL 60 | C14: =[1]Лист4!D16 -> 60 | D14: =[1]Лист4!F16 -> 0.53 | E14: =D14*C14 -> 31.8 | F14: =D14*1.18*0.07 -> 0.043778 | G14: =ROUND((((D14*1.15)*1.18)+F14+0.14)*1.2,2) -> 1.08 | H14: =ROUNDUP(G14*1.04*$N$1,2) -> 3.21 | I14: =ROUNDUP(G14*1.2*$N$1,2) -> 3.7 | J14: =ROUNDUP(G14*1.03*$N$1,2) -> 3.18 | K14: =N14*0.95 -> 0 | M14: =ROUNDUP(L14*0.88,2) -> 0 | N14: =ROUNDUP(L14*$N$1,2) -> 0 | O14: =ROUNDUP(N14*0.88,2) -> 0 | P14: =G14*C14 -> 64.8 | Q14: =L14*C14 -> 0 | R14: =Q14-P14 -> -64.8 | T14: R Tr Sno Trendsetter Water
A15: =[1]Лист4!A153 -> 8 | B15: =[1]Лист4!C153 -> AKM12 Статица розовая | C15: =[1]Лист4!D153 -> 50 | D15: =[1]Лист4!F153 -> 0.64 | E15: =D15*C15 -> 32 | F15: =D15*1.18*0.07 -> 0.052864 | G15: =ROUND((((D15*1.15)*1.18)+F15+0.14)*1.2,2) -> 1.27 | H15: =ROUNDUP(G15*1.04*$N$1,2) -> 3.77 | I15: =ROUNDUP(G15*1.2*$N$1,2) -> 4.35 | J15: =ROUNDUP(G15*1.03*$N$1,2) -> 3.73 | K15: =N15*0.95 -> 0 | M15: =ROUNDUP(L15*0.88,2) -> 0 | N15: =ROUNDUP(L15*$N$1,2) -> 0 | O15: =ROUNDUP(N15*0.88,2) -> 0 | P15: =G15*C15 -> 63.5 | Q15: =L15*C15 -> 0 | R15: =Q15-P15 -> -63.5 | T15: Lim S Fantasia Wings
A16: =[1]Лист4!A92 -> 8 | B16: =[1]Лист4!C92 -> AKM12 Хамелациум белый | C16: =[1]Лист4!D92 -> 50 | D16: =[1]Лист4!F92 -> 0.64 | E16: =D16*C16 -> 32 | F16: =D16*1.18*0.07 -> 0.052864 | G16: =ROUND((((D16*1.15)*1.18)+F16+0.14)*1.2,2) -> 1.27 | H16: =ROUNDUP(G16*1.04*$N$1,2) -> 3.77 | I16: =ROUNDUP(G16*1.2*$N$1,2) -> 4.35 | J16: =ROUNDUP(G16*1.03*$N$1,2) -> 3.73 | K16: =N16*0.95 -> 0 | M16: =ROUNDUP(L16*0.88,2) -> 0 | N16: =ROUNDUP(L16*$N$1,2) -> 0 | O16: =ROUNDUP(N16*0.88,2) -> 0 | P16: =G16*C16 -> 63.5 | Q16: =L16*C16 -> 0 | R16: =Q16-P16 -> -63.5 | T16: Chame Un Eve
A17: =[1]Лист4!A38 -> 2 | B17: =[1]Лист4!C38 -> AKM12 Хризантема сантини белая | C17: =[1]Лист4!D38 -> 50 | D17: =[1]Лист4!F38 -> 0.43 | E17: =D17*C17 -> 21.5 | F17: =D17*1.18*0.07 -> 0.035518 | G17: =ROUND((((D17*1.15)*1.18)+F17+0.14)*1.2,2) -> 0.91 | H17: =ROUNDUP(G17*1.04*$N$1,2) -> 2.7 | I17: =ROUNDUP(G17*1.2*$N$1,2) -> 3.12 | J17: =ROUNDUP(G17*1.03*$N$1,2) -> 2.68 | K17: =N17*0.95 -> 0 | M17: =ROUNDUP(L17*0.88,2) -> 0 | N17: =ROUNDUP(L17*$N$1,2) -> 0 | O17: =ROUNDUP(N17*0.88,2) -> 0 | P17: =G17*C17 -> 45.5 | Q17: =L17*C17 -> 0 | R17: =Q17-P17 -> -45.5 | T17: Chr S Mad Lindi Whit
A18: =[1]Лист4!A74 -> 8 | B18: =[1]Лист4!C74 -> AKM13 Аллиум | C18: =[1]Лист4!D74 -> 100 | D18: =[1]Лист4!F74 -> 0.01 | E18: =D18*C18 -> 1 | F18: =D18*1.18*0.07 -> 0.000826 | G18: =ROUND((((D18*1.15)*1.18)+F18+0.14)*1.2,2) -> 0.19 | H18: =ROUNDUP(G18*1.04*$N$1,2) -> 0.57 | I18: =ROUNDUP(G18*1.2*$N$1,2) -> 0.65 | J18: =ROUNDUP(G18*1.03*$N$1,2) -> 0.56 | K18: =N18*0.95 -> 0 | M18: =ROUNDUP(L18*0.88,2) -> 0 | N18: =ROUNDUP(L18*$N$1,2) -> 0 | O18: =ROUNDUP(N18*0.88,2) -> 0 | P18: =G18*C18 -> 19 | Q18: =L18*C18 -> 0 | R18: =Q18-P18 -> -19 | T18: Allium Ov
A19: =[1]Лист4!A100 -> 8 | B19: =[1]Лист4!C100 -> AKM13 Драцена флорида | C19: =[1]Лист4!D100 -> 50 | D19: =[1]Лист4!F100 -> 0.32 | E19: =D19*C19 -> 16 | F19: =D19*1.18*0.07 -> 0.026432 | G19: =ROUND((((D19*1.15)*1.18)+F19+0.14)*1.2,2) -> 0.72 | H19: =ROUNDUP(G19*1.04*$N$1,2) -> 2.14 | I19: =ROUNDUP(G19*1.2*$N$1,2) -> 2.47 | J19: =ROUNDUP(G19*1.03*$N$1,2) -> 2.12 | K19: =N19*0.95 -> 0 | M19: =ROUNDUP(L19*0.88,2) -> 0 | N19: =ROUNDUP(L19*$N$1,2) -> 0 | O19: =ROUNDUP(N19*0.88,2) -> 0 | P19: =G19*C19 -> 36 | Q19: =L19*C19 -> 0 | R19: =Q19-P19 -> -36 | T19: Drac Surculosa Florida Beauty
A20: =[1]Лист4!A198 -> 8 | B20: =[1]Лист4!C198 -> AKM13 Калла Раноми | C20: =[1]Лист4!D198 -> 20 | D20: =[1]Лист4!F198 -> 0.49 | E20: =D20*C20 -> 9.8 | F20: =D20*1.18*0.07 -> 0.040474 | G20: =ROUND((((D20*1.15)*1.18)+F20+0.14)*1.2,2) -> 1.01 | H20: =ROUNDUP(G20*1.04*$N$1,2) -> 3 | I20: =ROUNDUP(G20*1.2*$N$1,2) -> 3.46 | J20: =ROUNDUP(G20*1.03*$N$1,2) -> 2.97 | K20: =N20*0.95 -> 0 | M20: =ROUNDUP(L20*0.88,2) -> 0 | N20: =ROUNDUP(L20*$N$1,2) -> 0 | O20: =ROUNDUP(N20*0.88,2) -> 0 | P20: =G20*C20 -> 20.2 | Q20: =L20*C20 -> 0 | R20: =Q20-P20 -> -20.2 | T20: Zant Capt Ranomi
A21: =[1]Лист4!A70 -> 6 | B21: =[1]Лист4!C70 -> AKM13 Лилия белая | C21: =[1]Лист4!D70 -> 40 | D21: =[1]Лист4!F70 -> 1.1 | E21: =D21*C21 -> 44 | F21: =D21*1.18*0.07 -> 0.09086 | G21: =ROUND((((D21*1.15)*1.18)+F21+0.14)*1.2,2) -> 2.07 | H21: =ROUNDUP(G21*1.04*$N$1,2) -> 6.14 | I21: =ROUNDUP(G21*1.2*$N$1,2) -> 7.08 | J21: =ROUNDUP(G21*1.03*$N$1,2) -> 6.08 | K21: =N21*0.95 -> 0 | M21: =ROUNDUP(L21*0.88,2) -> 0 | N21: =ROUNDUP(L21*$N$1,2) -> 0 | O21: =ROUNDUP(N21*0.88,2) -> 0 | P21: =G21*C21 -> 82.8 | Q21: =L21*C21 -> 0 | R21: =Q21-P21 -> -82.8 | T21: Li Or Helvetia
A22: =[1]Лист4!A157 -> 8 | B22: =[1]Лист4!C157 -> AKM13 Лимониум белый | C22: =[1]Лист4!D157 -> 50 | D22: =[1]Лист4!F157 -> 0.32 | E22: =D22*C22 -> 16 | F22: =D22*1.18*0.07 -> 0.026432 | G22: =ROUND((((D22*1.15)*1.18)+F22+0.14)*1.2,2) -> 0.72 | H22: =ROUNDUP(G22*1.04*$N$1,2) -> 2.14 | I22: =ROUNDUP(G22*1.2*$N$1,2) -> 2.47 | J22: =ROUNDUP(G22*1.03*$N$1,2) -> 2.12 | K22: =N22*0.95 -> 0 | M22: =ROUNDUP(L22*0.88,2) -> 0 | N22: =ROUNDUP(L22*$N$1,2) -> 0 | O22: =ROUNDUP(N22*0.88,2) -> 0 | P22: =G22*C22 -> 36 | Q22: =L22*C22 -> 0 | R22: =Q22-P22 -> -36 | T22: Lim Sin Sen P Colada
A23: =[1]Лист4!A156 -> 8 | B23: =[1]Лист4!C156 -> AKM13 Лимониум синий | C23: =[1]Лист4!D156 -> 50 | D23: =[1]Лист4!F156 -> 0.37 | E23: =D23*C23 -> 18.5 | F23: =D23*1.18*0.07 -> 0.030562 | G23: =ROUND((((D23*1.15)*1.18)+F23+0.14)*1.2,2) -> 0.81 | H23: =ROUNDUP(G23*1.04*$N$1,2) -> 2.41 | I23: =ROUNDUP(G23*1.2*$N$1,2) -> 2.78 | J23: =ROUNDUP(G23*1.03*$N$1,2) -> 2.38 | K23: =N23*0.95 -> 0 | M23: =ROUNDUP(L23*0.88,2) -> 0 | N23: =ROUNDUP(L23*$N$1,2) -> 0 | O23: =ROUNDUP(N23*0.88,2) -> 0 | P23: =G23*C23 -> 40.5 | Q23: =L23*C23 -> 0 | R23: =Q23-P23 -> -40.5 | T23: Lim Saf Lilac
A24: =[1]Лист4!A166 -> 8 | B24: =[1]Лист4!C166 -> AKM13 Пион Диана | C24: =[1]Лист4!D166 -> 40 | D24: =[1]Лист4!F166 -> 0.58 | E24: =D24*C24 -> 23.2 | F24: =D24*1.18*0.07 -> 0.047908 | G24: =ROUND((((D24*1.15)*1.18)+F24+0.14)*1.2,2) -> 1.17 | H24: =ROUNDUP(G24*1.04*$N$1,2) -> 3.47 | I24: =ROUNDUP(G24*1.2*$N$1,2) -> 4.01 | J24: =ROUNDUP(G24*1.03*$N$1,2) -> 3.44 | K24: =N24*0.95 -> 0 | M24: =ROUNDUP(L24*0.88,2) -> 0 | N24: =ROUNDUP(L24*$N$1,2) -> 0 | O24: =ROUNDUP(N24*0.88,2) -> 0 | P24: =G24*C24 -> 46.8 | Q24: =L24*C24 -> 0 | R24: =Q24-P24 -> -46.8 | T24: Paeo Diana Parks
A25: =[1]Лист4!A171 -> 8 | B25: =[1]Лист4!C171 -> AKM13 Пион Карл | C25: =[1]Лист4!D171 -> 100 | D25: =[1]Лист4!F171 -> 0.53 | E25: =D25*C25 -> 53 | F25: =D25*1.18*0.07 -> 0.043778 | G25: =ROUND((((D25*1.15)*1.18)+F25+0.14)*1.2,2) -> 1.08 | H25: =ROUNDUP(G25*1.04*$N$1,2) -> 3.21 | I25: =ROUNDUP(G25*1.2*$N$1,2) -> 3.7 | J25: =ROUNDUP(G25*1.03*$N$1,2) -> 3.18 | K25: =N25*0.95 -> 0 | M25: =ROUNDUP(L25*0.88,2) -> 0 | N25: =ROUNDUP(L25*$N$1,2) -> 0 | O25: =ROUNDUP(N25*0.88,2) -> 0 | P25: =G25*C25 -> 108 | Q25: =L25*C25 -> 0 | R25: =Q25-P25 -> -108 | T25: Paeo L Karl Rosenf
A26: =[1]Лист4!A172 -> 8 | B26: =[1]Лист4!C172 -> AKM13 Пион мисс Америка | C26: =[1]Лист4!D172 -> 60 | D26: =[1]Лист4!F172 -> 0.45 | E26: =D26*C26 -> 27 | F26: =D26*1.18*0.07 -> 0.03717 | G26: =ROUND((((D26*1.15)*1.18)+F26+0.14)*1.2,2) -> 0.95 | H26: =ROUNDUP(G26*1.04*$N$1,2) -> 2.82 | I26: =ROUNDUP(G26*1.2*$N$1,2) -> 3.25 | J26: =ROUNDUP(G26*1.03*$N$1,2) -> 2.79 | K26: =N26*0.95 -> 0 | M26: =ROUNDUP(L26*0.88,2) -> 0 | N26: =ROUNDUP(L26*$N$1,2) -> 0 | O26: =ROUNDUP(N26*0.88,2) -> 0 | P26: =G26*C26 -> 57 | Q26: =L26*C26 -> 0 | R26: =Q26-P26 -> -57 | T26: Paeo L Miss America
A27: =[1]Лист4!A185 -> 8 | B27: =[1]Лист4!C185 -> AKM13 Ранункулус клуни Ханой | C27: =[1]Лист4!D185 -> 90 | D27: =[1]Лист4!F185 -> 2.18 | E27: =D27*C27 -> 196.2 | F27: =D27*1.18*0.07 -> 0.180068 | G27: =ROUND((((D27*1.15)*1.18)+F27+0.14)*1.2,2) -> 3.93 | H27: =ROUNDUP(G27*1.04*$N$1,2) -> 11.65 | I27: =ROUNDUP(G27*1.2*$N$1,2) -> 13.45 | J27: =ROUNDUP(G27*1.03*$N$1,2) -> 11.54 | K27: =N27*0.95 -> 0 | M27: =ROUNDUP(L27*0.88,2) -> 0 | N27: =ROUNDUP(L27*$N$1,2) -> 0 | O27: =ROUNDUP(N27*0.88,2) -> 0 | P27: =G27*C27 -> 353.7 | Q27: =L27*C27 -> 0 | R27: =Q27-P27 -> -353.7 | T27: Ran Su Hanoi
A28: =[1]Лист4!A11 -> 1 | B28: =[1]Лист4!C11 -> AKM13 Роза H3o NL 60 | C28: =[1]Лист4!D11 -> 120 | D28: =[1]Лист4!F11 -> 0.2 | E28: =D28*C28 -> 24 | F28: =D28*1.18*0.07 -> 0.01652 | G28: =ROUND((((D28*1.15)*1.18)+F28+0.14)*1.2,2) -> 0.51 | H28: =ROUNDUP(G28*1.04*$N$1,2) -> 1.52 | I28: =ROUNDUP(G28*1.2*$N$1,2) -> 1.75 | J28: =ROUNDUP(G28*1.03*$N$1,2) -> 1.5 | K28: =N28*0.95 -> 0 | M28: =ROUNDUP(L28*0.88,2) -> 0 | N28: =ROUNDUP(L28*$N$1,2) -> 0 | O28: =ROUNDUP(N28*0.88,2) -> 0 | P28: =G28*C28 -> 61.2 | Q28: =L28*C28 -> 0 | R28: =Q28-P28 -> -61.2 | T28: R Gr H3o
A29: =[1]Лист4!A10 -> 1 | B29: =[1]Лист4!C10 -> AKM13 Роза Бизу NL 60 | C29: =[1]Лист4!D10 -> 100 | D29: =[1]Лист4!F10 -> 0.2 | E29: =D29*C29 -> 20 | F29: =D29*1.18*0.07 -> 0.01652 | G29: =ROUND((((D29*1.15)*1.18)+F29+0.14)*1.2,2) -> 0.51 | H29: =ROUNDUP(G29*1.04*$N$1,2) -> 1.52 | I29: =ROUNDUP(G29*1.2*$N$1,2) -> 1.75 | J29: =ROUNDUP(G29*1.03*$N$1,2) -> 1.5 | K29: =N29*0.95 -> 0 | M29: =ROUNDUP(L29*0.88,2) -> 0 | N29: =ROUNDUP(L29*$N$1,2) -> 0 | O29: =ROUNDUP(N29*0.88,2) -> 0 | P29: =G29*C29 -> 51 | Q29: =L29*C29 -> 0 | R29: =Q29-P29 -> -51 | T29: R Gr Bisou
A30: =[1]Лист4!A3 -> 1 | B30: =[1]Лист4!C3 -> AKM13 Роза Бэбифейс NL 50 | C30: =[1]Лист4!D3 -> 100 | D30: =[1]Лист4!F3 -> 0.16 | E30: =D30*C30 -> 16 | F30: =D30*1.18*0.07 -> 0.013216 | G30: =ROUND((((D30*1.15)*1.18)+F30+0.14)*1.2,2) -> 0.44 | H30: =ROUNDUP(G30*1.04*$N$1,2) -> 1.31 | I30: =ROUNDUP(G30*1.2*$N$1,2) -> 1.51 | J30: =ROUNDUP(G30*1.03*$N$1,2) -> 1.3 | K30: =N30*0.95 -> 0 | M30: =ROUNDUP(L30*0.88,2) -> 0 | N30: =ROUNDUP(L30*$N$1,2) -> 0 | O30: =ROUNDUP(N30*0.88,2) -> 0 | P30: =G30*C30 -> 44 | Q30: =L30*C30 -> 0 | R30: =Q30-P30 -> -44 | T30: R Gr Babyface
A31: =[1]Лист4!A24 -> 1 | B31: =[1]Лист4!C24 -> AKM13 Роза ветвистая Роял Блаш NL 70 | C31: =[1]Лист4!D24 -> 40 | D31: =[1]Лист4!F24 -> 2.58 | E31: =D31*C31 -> 103.2 | F31: =D31*1.18*0.07 -> 0.213108 | G31: =ROUND((((D31*1.15)*1.18)+F31+0.14)*1.2,2) -> 4.63 | H31: =ROUNDUP(G31*1.04*$N$1,2) -> 13.73 | I31: =ROUNDUP(G31*1.2*$N$1,2) -> 15.84 | J31: =ROUNDUP(G31*1.03*$N$1,2) -> 13.6 | K31: =N31*0.95 -> 0 | M31: =ROUNDUP(L31*0.88,2) -> 0 | N31: =ROUNDUP(L31*$N$1,2) -> 0 | O31: =ROUNDUP(N31*0.88,2) -> 0 | P31: =G31*C31 -> 185.2 | Q31: =L31*C31 -> 0 | R31: =Q31-P31 -> -185.2 | T31: R Tr Royal Blush (vip)
A32: =[1]Лист4!A19 -> 1 | B32: =[1]Лист4!C19 -> AKM13 Роза Джэкпот NL 70 | C32: =[1]Лист4!D19 -> 100 | D32: =[1]Лист4!F19 -> 0.2 | E32: =D32*C32 -> 20 | F32: =D32*1.18*0.07 -> 0.01652 | G32: =ROUND((((D32*1.15)*1.18)+F32+0.14)*1.2,2) -> 0.51 | H32: =ROUNDUP(G32*1.04*$N$1,2) -> 1.52 | I32: =ROUNDUP(G32*1.2*$N$1,2) -> 1.75 | J32: =ROUNDUP(G32*1.03*$N$1,2) -> 1.5 | K32: =N32*0.95 -> 0 | M32: =ROUNDUP(L32*0.88,2) -> 0 | N32: =ROUNDUP(L32*$N$1,2) -> 0 | O32: =ROUNDUP(N32*0.88,2) -> 0 | P32: =G32*C32 -> 51 | Q32: =L32*C32 -> 0 | R32: =Q32-P32 -> -51 | T32: R Gr Jackpot+
A33: =[1]Лист4!A9 -> 1 | B33: =[1]Лист4!C9 -> AKM13 Роза дэвид аустин Пьюрити 50 | C33: =[1]Лист4!D9 -> 72 | D33: =[1]Лист4!F9 -> 2.55 | E33: =D33*C33 -> 183.6 | F33: =D33*1.18*0.07 -> 0.21063 | G33: =ROUND((((D33*1.15)*1.18)+F33+0.14)*1.2,2) -> 4.57 | H33: =ROUNDUP(G33*1.04*$N$1,2) -> 13.55 | I33: =ROUNDUP(G33*1.2*$N$1,2) -> 15.63 | J33: =ROUNDUP(G33*1.03*$N$1,2) -> 13.42 | K33: =N33*0.95 -> 0 | M33: =ROUNDUP(L33*0.88,2) -> 0 | N33: =ROUNDUP(L33*$N$1,2) -> 0 | O33: =ROUNDUP(N33*0.88,2) -> 0 | P33: =G33*C33 -> 329.04 | Q33: =L33*C33 -> 0 | R33: =Q33-P33 -> -329.04 | T33: Rosa David Austin Purity
A34: =[1]Лист4!A4 -> 1 | B34: =[1]Лист4!C4 -> AKM13 Роза Квиксэнд NL 50 | C34: =[1]Лист4!D4 -> 100 | D34: =[1]Лист4!F4 -> 0.99 | E34: =D34*C34 -> 99 | F34: =D34*1.18*0.07 -> 0.081774 | G34: =ROUND((((D34*1.15)*1.18)+F34+0.14)*1.2,2) -> 1.88 | H34: =ROUNDUP(G34*1.04*$N$1,2) -> 5.58 | I34: =ROUNDUP(G34*1.2*$N$1,2) -> 6.43 | J34: =ROUNDUP(G34*1.03*$N$1,2) -> 5.52 | K34: =N34*0.95 -> 0 | M34: =ROUNDUP(L34*0.88,2) -> 0 | N34: =ROUNDUP(L34*$N$1,2) -> 0 | O34: =ROUNDUP(N34*0.88,2) -> 0 | P34: =G34*C34 -> 188 | Q34: =L34*C34 -> 0 | R34: =Q34-P34 -> -188 | T34: R Gr Quicksand
A35: =[1]Лист4!A20 -> 1 | B35: =[1]Лист4!C20 -> AKM13 Роза Роял романс 70 | C35: =[1]Лист4!D20 -> 20 | D35: =[1]Лист4!F20 -> 1.58 | E35: =D35*C35 -> 31.6 | F35: =D35*1.18*0.07 -> 0.130508 | G35: =ROUND((((D35*1.15)*1.18)+F35+0.14)*1.2,2) -> 2.9 | H35: =ROUNDUP(G35*1.04*$N$1,2) -> 8.6 | I35: =ROUNDUP(G35*1.2*$N$1,2) -> 9.92 | J35: =ROUNDUP(G35*1.03*$N$1,2) -> 8.52 | K35: =N35*0.95 -> 0 | M35: =ROUNDUP(L35*0.88,2) -> 0 | N35: =ROUNDUP(L35*$N$1,2) -> 0 | O35: =ROUNDUP(N35*0.88,2) -> 0 | P35: =G35*C35 -> 58 | Q35: =L35*C35 -> 0 | R35: =Q35-P35 -> -58 | T35: R Gr Royal Romance
A36: =[1]Лист4!A154 -> 8 | B36: =[1]Лист4!C154 -> AKM13 Статица белая | C36: =[1]Лист4!D154 -> 25 | D36: =[1]Лист4!F154 -> 0.37 | E36: =D36*C36 -> 9.25 | F36: =D36*1.18*0.07 -> 0.030562 | G36: =ROUND((((D36*1.15)*1.18)+F36+0.14)*1.2,2) -> 0.81 | H36: =ROUNDUP(G36*1.04*$N$1,2) -> 2.41 | I36: =ROUNDUP(G36*1.2*$N$1,2) -> 2.78 | J36: =ROUNDUP(G36*1.03*$N$1,2) -> 2.38 | K36: =N36*0.95 -> 0 | M36: =ROUNDUP(L36*0.88,2) -> 0 | N36: =ROUNDUP(L36*$N$1,2) -> 0 | O36: =ROUNDUP(N36*0.88,2) -> 0 | P36: =G36*C36 -> 20.25 | Q36: =L36*C36 -> 0 | R36: =Q36-P36 -> -20.25 | T36: Lim S Frost Wings
A37: =[1]Лист4!A152 -> 8 | B37: =[1]Лист4!C152 -> AKM13 Статица синяя | C37: =[1]Лист4!D152 -> 25 | D37: =[1]Лист4!F152 -> 0.33 | E37: =D37*C37 -> 8.25 | F37: =D37*1.18*0.07 -> 0.027258 | G37: =ROUND((((D37*1.15)*1.18)+F37+0.14)*1.2,2) -> 0.74 | H37: =ROUNDUP(G37*1.04*$N$1,2) -> 2.2 | I37: =ROUNDUP(G37*1.2*$N$1,2) -> 2.54 | J37: =ROUNDUP(G37*1.03*$N$1,2) -> 2.18 | K37: =N37*0.95 -> 0 | M37: =ROUNDUP(L37*0.88,2) -> 0 | N37: =ROUNDUP(L37*$N$1,2) -> 0 | O37: =ROUNDUP(N37*0.88,2) -> 0 | P37: =G37*C37 -> 18.5 | Q37: =L37*C37 -> 0 | R37: =Q37-P37 -> -18.5 | T37: Lim S Cryst Dark Blu
A38: =[1]Лист4!A155 -> 8 | B38: =[1]Лист4!C155 -> AKM13 Статица сиреневая | C38: =[1]Лист4!D155 -> 25 | D38: =[1]Лист4!F155 -> 0.32 | E38: =D38*C38 -> 8 | F38: =D38*1.18*0.07 -> 0.026432 | G38: =ROUND((((D38*1.15)*1.18)+F38+0.14)*1.2,2) -> 0.72 | H38: =ROUNDUP(G38*1.04*$N$1,2) -> 2.14 | I38: =ROUNDUP(G38*1.2*$N$1,2) -> 2.47 | J38: =ROUNDUP(G38*1.03*$N$1,2) -> 2.12 | K38: =N38*0.95 -> 0 | M38: =ROUNDUP(L38*0.88,2) -> 0 | N38: =ROUNDUP(L38*$N$1,2) -> 0 | O38: =ROUNDUP(N38*0.88,2) -> 0 | P38: =G38*C38 -> 18 | Q38: =L38*C38 -> 0 | R38: =Q38-P38 -> -18 | T38: Lim S Tessa Malva
A39: =[1]Лист4!A28 -> 2 | B39: =[1]Лист4!C28 -> AKM13 Хризантема 1 Магнум | C39: =[1]Лист4!D28 -> 120 | D39: =[1]Лист4!F28 -> 0.46 | E39: =D39*C39 -> 55.2 | F39: =D39*1.18*0.07 -> 0.037996 | G39: =ROUND((((D39*1.15)*1.18)+F39+0.14)*1.2,2) -> 0.96 | H39: =ROUNDUP(G39*1.04*$N$1,2) -> 2.85 | I39: =ROUNDUP(G39*1.2*$N$1,2) -> 3.29 | J39: =ROUNDUP(G39*1.03*$N$1,2) -> 2.82 | K39: =N39*0.95 -> 0 | M39: =ROUNDUP(L39*0.88,2) -> 0 | N39: =ROUNDUP(L39*$N$1,2) -> 0 | O39: =ROUNDUP(N39*0.88,2) -> 0 | P39: =G39*C39 -> 115.2 | Q39: =L39*C39 -> 0 | R39: =Q39-P39 -> -115.2 | T39: Chr G Magnum
A40: =[1]Лист4!A30 -> 2 | B40: =[1]Лист4!C30 -> AKM13 Хризантема 1 Маракуя | C40: =[1]Лист4!D30 -> 60 | D40: =[1]Лист4!F30 -> 0.48 | E40: =D40*C40 -> 28.8 | F40: =D40*1.18*0.07 -> 0.039648 | G40: =ROUND((((D40*1.15)*1.18)+F40+0.14)*1.2,2) -> 1 | H40: =ROUNDUP(G40*1.04*$N$1,2) -> 2.97 | I40: =ROUNDUP(G40*1.2*$N$1,2) -> 3.42 | J40: =ROUNDUP(G40*1.03*$N$1,2) -> 2.94 | K40: =N40*0.95 -> 0 | M40: =ROUNDUP(L40*0.88,2) -> 0 | N40: =ROUNDUP(L40*$N$1,2) -> 0 | O40: =ROUNDUP(N40*0.88,2) -> 0 | P40: =G40*C40 -> 60 | Q40: =L40*C40 -> 0 | R40: =Q40-P40 -> -60 | T40: Chr G Maracuja
...
